<?xml version="1.0" encoding="utf-8"?>
<!-- This URDF was automatically created by SolidWorks to URDF Exporter! Originally created by Stephen Brawner (brawner@gmail.com) 
     Commit Version: 1.6.0-4-g7f85cfe  Build Version: 1.6.7995.38578
     For more information, please see http://wiki.ros.org/sw_urdf_exporter -->
<robot
  name="full-arm-mar24-urdf-and-meshes">
  <link
    name="base_link">
    <inertial>
      <origin
        xyz="0.8001 0.96967 1.6434"
        rpy="0 0 0" />
      <mass
        value="3.0245" />
      <inertia
        ixx="0.13578"
        ixy="-3.996E-13"
        ixz="-3.2341E-12"
        iyy="0.12646"
        iyz="-2.0376E-12"
        izz="0.13578" />
    </inertial>
    <visual>
      <origin
        xyz="0 0 0"
        rpy="0 0 0" />
      <geometry>
        <mesh
          filename="package://waybionic_description/meshes/base_link.STL" />
      </geometry>
      <material
        name="">
        <color
          rgba="0.79216 0.81961 0.93333 1" />
      </material>
    </visual>
    <collision>
      <origin
        xyz="0 0 0"
        rpy="0 0 0" />
      <geometry>
        <mesh
          filename="package://waybionic_description/meshes/base_link.STL" />
      </geometry>
    </collision>
  </link>
  <link
    name="shoulder">
    <inertial>
      <origin
        xyz="0.018803 -0.01167 8.6599E-06"
        rpy="0 0 0" />
      <mass
        value="0.73934" />
      <inertia
        ixx="0.0018615"
        ixy="-0.0003921"
        ixz="-1.0719E-07"
        iyy="0.0015793"
        iyz="9.4857E-08"
        izz="0.0021357" />
    </inertial>
    <visual>
      <origin
        xyz="0 0 0"
        rpy="0 0 0" />
      <geometry>
        <mesh
          filename="package://waybionic_description/meshes/shoulder.STL" />
      </geometry>
      <material
        name="">
        <color
          rgba="1 1 1 1" />
      </material>
    </visual>
    <collision>
      <origin
        xyz="0 0 0"
        rpy="0 0 0" />
      <geometry>
        <mesh
          filename="package://waybionic_description/meshes/shoulder.STL" />
      </geometry>
    </collision>
  </link>
  <joint
    name="joint1"
    type="fixed">
    <origin
      xyz="0.8001 -1.6434 1.3903"
      rpy="1.5708 0 -1.1999" />
    <parent
      link="base_link" />
    <child
      link="shoulder" />
    <axis
      xyz="0 0 0" />
    <limit
      lower="-3.14"
      upper="3.14"
      effort="100"
      velocity="1" />
  </joint>
  <link
    name="elbow">
    <inertial>
      <origin
        xyz="-0.10994 0.2063 0.060408"
        rpy="0 0 0" />
      <mass
        value="1.6571" />
      <inertia
        ixx="0.0040049"
        ixy="9.7618E-05"
        ixz="2.4251E-05"
        iyy="0.0020313"
        iyz="-0.00043052"
        izz="0.0038422" />
    </inertial>
    <visual>
      <origin
        xyz="0 0 0"
        rpy="0 0 0" />
      <geometry>
        <mesh
          filename="package://waybionic_description/meshes/elbow.STL" />
      </geometry>
      <material
        name="">
        <color
          rgba="0.75294 0.75294 0.75294 1" />
      </material>
    </visual>
    <collision>
      <origin
        xyz="0 0 0"
        rpy="0 0 0" />
      <geometry>
        <mesh
          filename="package://waybionic_description/meshes/elbow.STL" />
      </geometry>
    </collision>
  </link>
  <joint
    name="joint2"
    type="fixed">
    <origin
      xyz="0.10285 0.058129 0.011405"
      rpy="2.8569 0 -3.1416" />
    <parent
      link="shoulder" />
    <child
      link="elbow" />
    <axis
      xyz="0 0 0" />
    <limit
      lower="-3.14"
      upper="3.14"
      effort="100"
      velocity="1" />
  </joint>
  <link
    name="forearm">
    <inertial>
      <origin
        xyz="1.3362E-05 0.054674 0.026205"
        rpy="0 0 0" />
      <mass
        value="1.1398" />
      <inertia
        ixx="0.0017411"
        ixy="4.9339E-08"
        ixz="3.3313E-07"
        iyy="0.0015113"
        iyz="2.8369E-05"
        izz="0.0013902" />
    </inertial>
    <visual>
      <origin
        xyz="0 0 0"
        rpy="0 0 0" />
      <geometry>
        <mesh
          filename="package://waybionic_description/meshes/forearm.STL" />
      </geometry>
      <material
        name="">
        <color
          rgba="0.75294 0.75294 0.75294 1" />
      </material>
    </visual>
    <collision>
      <origin
        xyz="0 0 0"
        rpy="0 0 0" />
      <geometry>
        <mesh
          filename="package://waybionic_description/meshes/forearm.STL" />
      </geometry>
    </collision>
  </link>
  <joint
    name="joint3"
    type="continuous">
    <origin
      xyz="0.00017 0.47022 0.10797"
      rpy="0.84036 -1.4494 -0.82578" />
    <parent
      link="elbow" />
    <child
      link="forearm" />
    <axis
      xyz="0 0 1" />
    <limit
      lower="-3.14"
      upper="3.14"
      effort="100"
      velocity="1" />
  </joint>
  <link
    name="wrist">
    <inertial>
      <origin
        xyz="0.00079289 0.048601 1.9326E-06"
        rpy="0 0 0" />
      <mass
        value="0.36714" />
      <inertia
        ixx="0.00049207"
        ixy="-1.7262E-06"
        ixz="-1.746E-08"
        iyy="0.00050366"
        iyz="6.9145E-09"
        izz="0.00034393" />
    </inertial>
    <visual>
      <origin
        xyz="0 0 0"
        rpy="0 0 0" />
      <geometry>
        <mesh
          filename="package://waybionic_description/meshes/wrist.STL" />
      </geometry>
      <material
        name="">
        <color
          rgba="0.79216 0.81961 0.93333 1" />
      </material>
    </visual>
    <collision>
      <origin
        xyz="0 0 0"
        rpy="0 0 0" />
      <geometry>
        <mesh
          filename="package://waybionic_description/meshes/wrist.STL" />
      </geometry>
    </collision>
  </link>
  <joint
    name="joint4"
    type="fixed">
    <origin
      xyz="0 0.210000000000002 0.0132179574096474"
      rpy="0 0 0" />
    <parent
      link="forearm" />
    <child
      link="wrist" />
    <axis
      xyz="0 0 0" />
  </joint>
</robot>